 * Serving Flask app 'app' (lazy loading)
 * Environment: production
   WARNING: This is a development server. Do not use it in a production deployment.
   Use a production WSGI server instead.
 * Debug mode: off
 * Running on all addresses.
   WARNING: This is a development server. Do not use it in a production deployment.
 * Running on https://172.26.7.13:5000/ (Press CTRL+C to quit)
 * Serving Flask app 'app' (lazy loading)
 * Environment: production
   WARNING: This is a development server. Do not use it in a production deployment.
   Use a production WSGI server instead.
 * Debug mode: off
 * Running on all addresses.
   WARNING: This is a development server. Do not use it in a production deployment.
 * Running on https://172.26.7.13:5000/ (Press CTRL+C to quit)
INFO: Created TensorFlow Lite XNNPACK delegate for CPU.
104.28.4.77 - - [20/Jun/2021 00:52:29] "POST /process HTTP/1.1" 200 -
[2021-06-20 01:05:40,043] ERROR in app: Exception on /process [POST]
Traceback (most recent call last):
  File "/home/ubuntu/.local/lib/python3.6/site-packages/flask/app.py", line 2070, in wsgi_app
    response = self.full_dispatch_request()
  File "/home/ubuntu/.local/lib/python3.6/site-packages/flask/app.py", line 1515, in full_dispatch_request
    rv = self.handle_user_exception(e)
  File "/home/ubuntu/.local/lib/python3.6/site-packages/flask_cors/extension.py", line 165, in wrapped_function
    return cors_after_request(app.make_response(f(*args, **kwargs)))
  File "/home/ubuntu/.local/lib/python3.6/site-packages/flask/app.py", line 1513, in full_dispatch_request
    rv = self.dispatch_request()
  File "/home/ubuntu/.local/lib/python3.6/site-packages/flask/app.py", line 1499, in dispatch_request
    return self.ensure_sync(self.view_functions[rule.endpoint])(**req.view_args)
  File "app.py", line 19, in process
    dst = correct.correct(src)
  File "/home/ubuntu/insta-shot/server/correct.py", line 14, in correct
    results = pose.process(img)
  File "/home/ubuntu/.local/lib/python3.6/site-packages/mediapipe/python/solutions/pose.py", line 192, in process
    results = super().process(input_data={'image': image})
  File "/home/ubuntu/.local/lib/python3.6/site-packages/mediapipe/python/solution_base.py", line 299, in process
    data).at(self._simulated_timestamp))
  File "/home/ubuntu/.local/lib/python3.6/site-packages/mediapipe/python/solution_base.py", line 475, in _make_packet
    data, image_format=image_frame.ImageFormat.SRGB)
  File "/home/ubuntu/.local/lib/python3.6/site-packages/mediapipe/python/packet_creator.py", line 143, in create_image_frame
    image_format, data, copy)
TypeError: Cannot cast array data from dtype('uint16') to dtype('uint8') according to the rule 'safe'
104.28.4.78 - - [20/Jun/2021 01:05:40] "POST /process HTTP/1.1" 500 -
74.120.14.56 - - [20/Jun/2021 05:41:59] "GET / HTTP/1.1" 200 -
74.120.14.56 - - [20/Jun/2021 05:42:00] "GET / HTTP/1.1" 200 -
104.28.4.77 - - [20/Jun/2021 10:28:45] "POST /process HTTP/1.1" 200 -
162.142.125.53 - - [20/Jun/2021 12:59:35] "GET / HTTP/1.1" 200 -
162.142.125.53 - - [20/Jun/2021 12:59:36] "GET / HTTP/1.1" 200 -
128.14.209.242 - - [20/Jun/2021 13:11:46] "GET / HTTP/1.1" 200 -
14.32.142.30 - - [20/Jun/2021 17:49:43] "POST /process HTTP/1.1" 200 -
162.142.125.38 - - [20/Jun/2021 19:28:40] "GET / HTTP/1.1" 200 -
162.142.125.38 - - [20/Jun/2021 19:28:41] "GET / HTTP/1.1" 200 -
162.142.125.40 - - [20/Jun/2021 23:48:21] "GET / HTTP/1.1" 200 -
162.142.125.40 - - [20/Jun/2021 23:48:22] "GET / HTTP/1.1" 200 -
121.88.168.222 - - [21/Jun/2021 02:51:10] "POST /process HTTP/1.1" 200 -
121.88.168.222 - - [21/Jun/2021 02:51:27] "POST /process HTTP/1.1" 200 -
104.28.4.78 - - [21/Jun/2021 03:27:03] "POST /process HTTP/1.1" 200 -
110.70.57.178 - - [21/Jun/2021 03:41:21] "POST /process HTTP/1.1" 200 -
Traceback (most recent call last):
  File "app.py", line 18, in <module>
    class logs(db.Model):
  File "/home/ubuntu/.local/lib/python3.6/site-packages/flask_sqlalchemy/model.py", line 67, in __init__
    super(NameMetaMixin, cls).__init__(name, bases, d)
  File "/home/ubuntu/.local/lib/python3.6/site-packages/flask_sqlalchemy/model.py", line 121, in __init__
    super(BindMetaMixin, cls).__init__(name, bases, d)
  File "/home/ubuntu/.local/lib/python3.6/site-packages/sqlalchemy/orm/decl_api.py", line 72, in __init__
    _as_declarative(reg, cls, dict_)
  File "/home/ubuntu/.local/lib/python3.6/site-packages/sqlalchemy/orm/decl_base.py", line 126, in _as_declarative
    return _MapperConfig.setup_mapping(registry, cls, dict_, None, {})
  File "/home/ubuntu/.local/lib/python3.6/site-packages/sqlalchemy/orm/decl_base.py", line 177, in setup_mapping
    return cfg_cls(registry, cls_, dict_, table, mapper_kw)
  File "/home/ubuntu/.local/lib/python3.6/site-packages/sqlalchemy/orm/decl_base.py", line 314, in __init__
    self._early_mapping(mapper_kw)
  File "/home/ubuntu/.local/lib/python3.6/site-packages/sqlalchemy/orm/decl_base.py", line 200, in _early_mapping
    self.map(mapper_kw)
  File "/home/ubuntu/.local/lib/python3.6/site-packages/sqlalchemy/orm/decl_base.py", line 992, in map
    mapper_cls(self.cls, self.local_table, **self.mapper_args),
  File "<string>", line 2, in __init__
  File "/home/ubuntu/.local/lib/python3.6/site-packages/sqlalchemy/util/deprecations.py", line 298, in warned
    return fn(*args, **kwargs)
  File "/home/ubuntu/.local/lib/python3.6/site-packages/sqlalchemy/orm/mapper.py", line 686, in __init__
    self._configure_pks()
  File "/home/ubuntu/.local/lib/python3.6/site-packages/sqlalchemy/orm/mapper.py", line 1331, in _configure_pks
    % (self, self.persist_selectable.description)
sqlalchemy.exc.ArgumentError: Mapper mapped class logs->logs could not assemble any primary key columns for mapped table 'logs'
Traceback (most recent call last):
  File "app.py", line 18, in <module>
    class logs(db.Model):
  File "/home/ubuntu/.local/lib/python3.6/site-packages/flask_sqlalchemy/model.py", line 67, in __init__
    super(NameMetaMixin, cls).__init__(name, bases, d)
  File "/home/ubuntu/.local/lib/python3.6/site-packages/flask_sqlalchemy/model.py", line 121, in __init__
    super(BindMetaMixin, cls).__init__(name, bases, d)
  File "/home/ubuntu/.local/lib/python3.6/site-packages/sqlalchemy/orm/decl_api.py", line 72, in __init__
    _as_declarative(reg, cls, dict_)
  File "/home/ubuntu/.local/lib/python3.6/site-packages/sqlalchemy/orm/decl_base.py", line 126, in _as_declarative
    return _MapperConfig.setup_mapping(registry, cls, dict_, None, {})
  File "/home/ubuntu/.local/lib/python3.6/site-packages/sqlalchemy/orm/decl_base.py", line 177, in setup_mapping
    return cfg_cls(registry, cls_, dict_, table, mapper_kw)
  File "/home/ubuntu/.local/lib/python3.6/site-packages/sqlalchemy/orm/decl_base.py", line 314, in __init__
    self._early_mapping(mapper_kw)
  File "/home/ubuntu/.local/lib/python3.6/site-packages/sqlalchemy/orm/decl_base.py", line 200, in _early_mapping
    self.map(mapper_kw)
  File "/home/ubuntu/.local/lib/python3.6/site-packages/sqlalchemy/orm/decl_base.py", line 992, in map
    mapper_cls(self.cls, self.local_table, **self.mapper_args),
  File "<string>", line 2, in __init__
  File "/home/ubuntu/.local/lib/python3.6/site-packages/sqlalchemy/util/deprecations.py", line 298, in warned
    return fn(*args, **kwargs)
  File "/home/ubuntu/.local/lib/python3.6/site-packages/sqlalchemy/orm/mapper.py", line 686, in __init__
    self._configure_pks()
  File "/home/ubuntu/.local/lib/python3.6/site-packages/sqlalchemy/orm/mapper.py", line 1331, in _configure_pks
    % (self, self.persist_selectable.description)
sqlalchemy.exc.ArgumentError: Mapper mapped class logs->logs could not assemble any primary key columns for mapped table 'logs'
Traceback (most recent call last):
  File "app.py", line 18, in <module>
    class logs(db.Model):
  File "/home/ubuntu/.local/lib/python3.6/site-packages/flask_sqlalchemy/model.py", line 67, in __init__
    super(NameMetaMixin, cls).__init__(name, bases, d)
  File "/home/ubuntu/.local/lib/python3.6/site-packages/flask_sqlalchemy/model.py", line 121, in __init__
    super(BindMetaMixin, cls).__init__(name, bases, d)
  File "/home/ubuntu/.local/lib/python3.6/site-packages/sqlalchemy/orm/decl_api.py", line 72, in __init__
    _as_declarative(reg, cls, dict_)
  File "/home/ubuntu/.local/lib/python3.6/site-packages/sqlalchemy/orm/decl_base.py", line 126, in _as_declarative
    return _MapperConfig.setup_mapping(registry, cls, dict_, None, {})
  File "/home/ubuntu/.local/lib/python3.6/site-packages/sqlalchemy/orm/decl_base.py", line 177, in setup_mapping
    return cfg_cls(registry, cls_, dict_, table, mapper_kw)
  File "/home/ubuntu/.local/lib/python3.6/site-packages/sqlalchemy/orm/decl_base.py", line 314, in __init__
    self._early_mapping(mapper_kw)
  File "/home/ubuntu/.local/lib/python3.6/site-packages/sqlalchemy/orm/decl_base.py", line 200, in _early_mapping
    self.map(mapper_kw)
  File "/home/ubuntu/.local/lib/python3.6/site-packages/sqlalchemy/orm/decl_base.py", line 992, in map
    mapper_cls(self.cls, self.local_table, **self.mapper_args),
  File "<string>", line 2, in __init__
  File "/home/ubuntu/.local/lib/python3.6/site-packages/sqlalchemy/util/deprecations.py", line 298, in warned
    return fn(*args, **kwargs)
  File "/home/ubuntu/.local/lib/python3.6/site-packages/sqlalchemy/orm/mapper.py", line 686, in __init__
    self._configure_pks()
  File "/home/ubuntu/.local/lib/python3.6/site-packages/sqlalchemy/orm/mapper.py", line 1331, in _configure_pks
    % (self, self.persist_selectable.description)
sqlalchemy.exc.ArgumentError: Mapper mapped class logs->logs could not assemble any primary key columns for mapped table 'logs'
Traceback (most recent call last):
  File "app.py", line 18, in <module>
    class logs(db.Model):
  File "/home/ubuntu/.local/lib/python3.6/site-packages/flask_sqlalchemy/model.py", line 67, in __init__
    super(NameMetaMixin, cls).__init__(name, bases, d)
  File "/home/ubuntu/.local/lib/python3.6/site-packages/flask_sqlalchemy/model.py", line 121, in __init__
    super(BindMetaMixin, cls).__init__(name, bases, d)
  File "/home/ubuntu/.local/lib/python3.6/site-packages/sqlalchemy/orm/decl_api.py", line 72, in __init__
    _as_declarative(reg, cls, dict_)
  File "/home/ubuntu/.local/lib/python3.6/site-packages/sqlalchemy/orm/decl_base.py", line 126, in _as_declarative
    return _MapperConfig.setup_mapping(registry, cls, dict_, None, {})
  File "/home/ubuntu/.local/lib/python3.6/site-packages/sqlalchemy/orm/decl_base.py", line 177, in setup_mapping
    return cfg_cls(registry, cls_, dict_, table, mapper_kw)
  File "/home/ubuntu/.local/lib/python3.6/site-packages/sqlalchemy/orm/decl_base.py", line 314, in __init__
    self._early_mapping(mapper_kw)
  File "/home/ubuntu/.local/lib/python3.6/site-packages/sqlalchemy/orm/decl_base.py", line 200, in _early_mapping
    self.map(mapper_kw)
  File "/home/ubuntu/.local/lib/python3.6/site-packages/sqlalchemy/orm/decl_base.py", line 992, in map
    mapper_cls(self.cls, self.local_table, **self.mapper_args),
  File "<string>", line 2, in __init__
  File "/home/ubuntu/.local/lib/python3.6/site-packages/sqlalchemy/util/deprecations.py", line 298, in warned
    return fn(*args, **kwargs)
  File "/home/ubuntu/.local/lib/python3.6/site-packages/sqlalchemy/orm/mapper.py", line 686, in __init__
    self._configure_pks()
  File "/home/ubuntu/.local/lib/python3.6/site-packages/sqlalchemy/orm/mapper.py", line 1331, in _configure_pks
    % (self, self.persist_selectable.description)
sqlalchemy.exc.ArgumentError: Mapper mapped class logs->logs could not assemble any primary key columns for mapped table 'logs'
Traceback (most recent call last):
  File "app.py", line 18, in <module>
    class logs(db.Model):
  File "/home/ubuntu/.local/lib/python3.6/site-packages/flask_sqlalchemy/model.py", line 67, in __init__
    super(NameMetaMixin, cls).__init__(name, bases, d)
  File "/home/ubuntu/.local/lib/python3.6/site-packages/flask_sqlalchemy/model.py", line 121, in __init__
    super(BindMetaMixin, cls).__init__(name, bases, d)
  File "/home/ubuntu/.local/lib/python3.6/site-packages/sqlalchemy/orm/decl_api.py", line 72, in __init__
    _as_declarative(reg, cls, dict_)
  File "/home/ubuntu/.local/lib/python3.6/site-packages/sqlalchemy/orm/decl_base.py", line 126, in _as_declarative
    return _MapperConfig.setup_mapping(registry, cls, dict_, None, {})
  File "/home/ubuntu/.local/lib/python3.6/site-packages/sqlalchemy/orm/decl_base.py", line 177, in setup_mapping
    return cfg_cls(registry, cls_, dict_, table, mapper_kw)
  File "/home/ubuntu/.local/lib/python3.6/site-packages/sqlalchemy/orm/decl_base.py", line 314, in __init__
    self._early_mapping(mapper_kw)
  File "/home/ubuntu/.local/lib/python3.6/site-packages/sqlalchemy/orm/decl_base.py", line 200, in _early_mapping
    self.map(mapper_kw)
  File "/home/ubuntu/.local/lib/python3.6/site-packages/sqlalchemy/orm/decl_base.py", line 992, in map
    mapper_cls(self.cls, self.local_table, **self.mapper_args),
  File "<string>", line 2, in __init__
  File "/home/ubuntu/.local/lib/python3.6/site-packages/sqlalchemy/util/deprecations.py", line 298, in warned
    return fn(*args, **kwargs)
  File "/home/ubuntu/.local/lib/python3.6/site-packages/sqlalchemy/orm/mapper.py", line 686, in __init__
    self._configure_pks()
  File "/home/ubuntu/.local/lib/python3.6/site-packages/sqlalchemy/orm/mapper.py", line 1331, in _configure_pks
    % (self, self.persist_selectable.description)
sqlalchemy.exc.ArgumentError: Mapper mapped class logs->logs could not assemble any primary key columns for mapped table 'logs'
Traceback (most recent call last):
  File "app.py", line 18, in <module>
    class logs(db.Model):
  File "/home/ubuntu/.local/lib/python3.6/site-packages/flask_sqlalchemy/model.py", line 67, in __init__
    super(NameMetaMixin, cls).__init__(name, bases, d)
  File "/home/ubuntu/.local/lib/python3.6/site-packages/flask_sqlalchemy/model.py", line 121, in __init__
    super(BindMetaMixin, cls).__init__(name, bases, d)
  File "/home/ubuntu/.local/lib/python3.6/site-packages/sqlalchemy/orm/decl_api.py", line 72, in __init__
    _as_declarative(reg, cls, dict_)
  File "/home/ubuntu/.local/lib/python3.6/site-packages/sqlalchemy/orm/decl_base.py", line 126, in _as_declarative
    return _MapperConfig.setup_mapping(registry, cls, dict_, None, {})
  File "/home/ubuntu/.local/lib/python3.6/site-packages/sqlalchemy/orm/decl_base.py", line 177, in setup_mapping
    return cfg_cls(registry, cls_, dict_, table, mapper_kw)
  File "/home/ubuntu/.local/lib/python3.6/site-packages/sqlalchemy/orm/decl_base.py", line 314, in __init__
    self._early_mapping(mapper_kw)
  File "/home/ubuntu/.local/lib/python3.6/site-packages/sqlalchemy/orm/decl_base.py", line 200, in _early_mapping
    self.map(mapper_kw)
  File "/home/ubuntu/.local/lib/python3.6/site-packages/sqlalchemy/orm/decl_base.py", line 992, in map
    mapper_cls(self.cls, self.local_table, **self.mapper_args),
  File "<string>", line 2, in __init__
  File "/home/ubuntu/.local/lib/python3.6/site-packages/sqlalchemy/util/deprecations.py", line 298, in warned
    return fn(*args, **kwargs)
  File "/home/ubuntu/.local/lib/python3.6/site-packages/sqlalchemy/orm/mapper.py", line 686, in __init__
    self._configure_pks()
  File "/home/ubuntu/.local/lib/python3.6/site-packages/sqlalchemy/orm/mapper.py", line 1331, in _configure_pks
    % (self, self.persist_selectable.description)
sqlalchemy.exc.ArgumentError: Mapper mapped class logs->logs could not assemble any primary key columns for mapped table 'logs'
